# 第十三讲-异常处理
Python 内置了一系列异常类，都由基类 Exception 派生出来。
[![rYOUOA.jpg](https://s3.ax1x.com/2020/12/18/rYOUOA.jpg)](https://imgchr.com/i/rYOUOA)
[![rYONyd.jpg](https://s3.ax1x.com/2020/12/18/rYONyd.jpg)](https://imgchr.com/i/rYONyd)

## 用 try-except 复合语句处理异常
``python
try:
    可能有异常的语句块
except:
    异常处理语句
```
例程：
```python
a,b=eval(input('input a,b for a/b'))
try:
    s = a/b
    print(s)
except:
    print('wdnmd!\n')
```
运行结果：
```
================= RESTART: D:/PythonProjects/tryandexcept.py =================
input a,b for a/b
2,1
2.0
>>> 
================= RESTART: D:/PythonProjects/tryandexcept.py =================
input a,b for a/b
2,0
wdnmd!
```
### 分类处理异常
```python
try:
    可能出现异常的语句块
except 异常类型1 as 错误描述:
    异常处理语句块1
except 异常类型2 as 错误描述:
    异常处理语句块2
...
except 异常类型n as 错误描述:
    异常处理语句块n
except:
    其他异常处理语句块1（类似于switch-case语句的default）
else:
    没有异常的话，执行这里的语句块
```

`as 错误描述`这一部分可以省略。

这个不省略的话，可以调用这个 `错误描述`。`错误描述` 是一个变量，其值是一个字符串，

字符串的串值与异常所对应的类有关，

比如 ZeroDivisionError （除以 0 异常类）返回的错误描述就是 `division by zero`。
### 嵌套 try-except 块的行为
先在外层 try，如果外层语句块没问题，顺序执行到内层 try。

except 接收异常时，若内层异常种类不匹配，由外层 except 接收；如果外层也不匹配，Python 会进行程序报错，即默认的异常处理方式。
## try-finally 处理异常
```python
try:
    可能有异常的语句块
finally:
    语句
```
finally 后面的语句块，不论异常是否发生，都要执行。
## assert 断言语句
```python
assert 逻辑表达式, 错误字符串
```
当执行到此语句时，检查逻辑表达式是否为 True。

是，什么也不发生，断言通过；

否，抛 AssertionError 异常，显示 `错误字符串`。

AssertionError 可以被 try-except 语句捕获和处理。

如果不作处理，程序就会被终止，Python 输出默认报错信息，报 AssertionError。

如果用 try-except 语句捕获 AssertionError 异常，

`except AssertionError as 错误信息`

中的 `错误信息` 的值就是 `错误字符串`。
## 自定义异常
### 手动引发异常
Python 使用 `raise` 显式引发异常。
```python
raise 异常类类名(提示字符串)
```
抛出一个属于 `异常类类名` 的异常，提示 `提示字符串`。

本质上 `异常类类名(提示字符串)` 是类的构造方法。
### 自定义异常类
自定义的异常类必须继承 Exception 类。

自定义的异常类不会被系统引发，必须通过手动 `raise` 来引发。
例：创建异常类NumberError.py。
```python
class NumberError(Exception):
def __init__()(self,data):
    self.data=data
```
